2024-12-16 21:55:31,388 | ERROR | Ошибка
Traceback (most recent call last):
  File "C:\Users\Даниил\Desktop\IT\2_round\Логирование\tests_12_4.py", line 26, in test_run
    r2 = rt.Runner(19, 15)
  File "C:\Users\Даниил\Desktop\IT\2_round\Логирование\mult.py", line 6, in __init__
    raise TypeError(f'Имя может быть только строкой, передано {type(name).__name__}')
TypeError: Имя может быть только строкой, передано int
2024-12-16 21:55:31,405 | WARNING | Неверный тип данных для объекта Runner
2024-12-16 21:55:31,406 | INFO | "test_run" выполнен успешно
2024-12-16 21:55:31,408 | ERROR | Ошибка
Traceback (most recent call last):
  File "C:\Users\Даниил\Desktop\IT\2_round\Логирование\tests_12_4.py", line 15, in test_walk
    r1 = rt.Runner('Name', -10)  # , speed=10)
  File "C:\Users\Даниил\Desktop\IT\2_round\Логирование\mult.py", line 11, in __init__
    raise ValueError(f'Скорость не может быть отрицательной, сейчас {speed}')
ValueError: Скорость не может быть отрицательной, сейчас -10
2024-12-16 21:55:31,411 | WARNING | Неверная скорость для Runner
2024-12-16 21:55:31,411 | INFO | "test_walk" выполнен успешно
